Workbook

Sheet Start Here
A1: RuskiMaxxing Supertotal - 1-Year Strength, Mass & Power Program
A2: Yellow cells are yours to fill in.
A3: Intake | F3: PR board
A4: Name (optional) | F4: Lift | G4: Best est. 1RM | H4: 1RM | I4: 3RM | J4: 5RM | K4: 10RM
A5: Units | B5: lb | F5: Squat | G5: =PRs!C2 | H5: =PRs!D2 | I5: =PRs!F2 | J5: =PRs!H2 | K5: =PRs!K2
A6: Round weights to nearest | B6: 5 | F6: Bench Press | G6: =PRs!C3 | H6: =PRs!D3 | I6: =PRs!F3 | J6: =PRs!H3 | K6: =PRs!K3
A7: Start date (a Monday) | B7: 46293 | F7: Deadlift | G7: =PRs!C4 | H7: =PRs!D4 | I7: =PRs!F4 | J7: =PRs!H4 | K7: =PRs!K4
A8: Height (inches if lb, cm if kg) | F8: Overhead Press | G8: =PRs!C5 | H8: =PRs!D5 | I8: =PRs!F5 | J8: =PRs!H5 | K8: =PRs!K5
A9: Starting bodyweight | F9: Snatch | G9: =PRs!C6 | H9: =PRs!D6 | I9: =PRs!F6 | J9: =PRs!H6 | K9: =PRs!K6
A10: Starting body fat % (optional) | F10: Clean & Jerk | G10: =PRs!C7 | H10: =PRs!D7 | I10: =PRs!F7 | J10: =PRs!H7 | K10: =PRs!K7
A11: Body fat method | F11: Total (e1RM) | G11: =G5+G6+G7+G8+G9+G10
A12: Age (optional)
A13: Sex (optional) | F13: Box jump standards (from your height)
F14: Level | G14: Box height | H14: Target | I14: Reached?
A15: Starting maxes (any movement or variation) | F15: Beginner | G15: 1 step | H15: =IF('Start Here'!$B$5="kg",19,7.5) | I15: =IF(AND(ISNUMBER(H15),PRs!D69>0),IF(PRs!D69>=H15,"YES",""),"")
A16: Exercise | B16: Weight | C16: Reps | D16: Est. 1RM | F16: Intermediate | G16: above knee | H16: =IF('Start Here'!$B$8="","enter height",ROUND('Start Here'!$B$8*0.3,1)) | I16: =IF(AND(ISNUMBER(H16),PRs!D69>0),IF(PRs!D69>=H16,"YES",""),"")
A17: Squat | D17: =IF(OR(B17="",C17=""),"",IF(C17=1,B17,ROUND(B17*(1+C17/30),1))) | F17: Proficient | G17: chest height | H17: =IF('Start Here'!$B$8="","enter height",ROUND('Start Here'!$B$8*0.72,1)) | I17: =IF(AND(ISNUMBER(H17),PRs!D69>0),IF(PRs!D69>=H17,"YES",""),"")
A18: Bench Press | D18: =IF(OR(B18="",C18=""),"",IF(C18=1,B18,ROUND(B18*(1+C18/30),1))) | F18: Elite | G18: head height | H18: =IF('Start Here'!$B$8="","enter height",ROUND('Start Here'!$B$8*0.93,1)) | I18: =IF(AND(ISNUMBER(H18),PRs!D69>0),IF(PRs!D69>=H18,"YES",""),"")
A19: Deadlift | D19: =IF(OR(B19="",C19=""),"",IF(C19=1,B19,ROUND(B19*(1+C19/30),1))) | F19: Your best box jump | H19: =PRs!D69
A20: Overhead Press | D20: =IF(OR(B20="",C20=""),"",IF(C20=1,B20,ROUND(B20*(1+C20/30),1))) | F20: Your level | H20: =IF(PRs!D69=0,"Not tested",IF(ISNUMBER('Start Here'!$H$18)*(PRs!D69>='Start Here'!$H$18),"Elite",IF(ISNUMBER('Start Here'!$H$17)*(PRs!D69>='Start Here'!$H$17),"Proficient",IF(ISNUMBER('Start Here'!$H$16)*(PRs!D69>='Start Here'!$H$16),"Intermediate",IF(PRs!D69>='Start Here'!$H$15,"Beginner","Below beginner")))))
A21: Snatch | D21: =IF(OR(B21="",C21=""),"",IF(C21=1,B21,ROUND(B21*(1+C21/30),1))) | F21: 1 step = beginner, above knee = intermediate, chest = proficient, head height = elite. Same unit as your height.
A22: Clean & Jerk | D22: =IF(OR(B22="",C22=""),"",IF(C22=1,B22,ROUND(B22*(1+C22/30),1)))
A23: Box Squat | D23: =IF(OR(B23="",C23=""),"",IF(C23=1,B23,ROUND(B23*(1+C23/30),1))) | F23: Prilepin's chart
A24: Close-Grip Bench Press | D24: =IF(OR(B24="",C24=""),"",IF(C24=1,B24,ROUND(B24*(1+C24/30),1))) | F24: % of max | G24: Reps per set | H24: Optimal total | I24: Total range
A25: Romanian Deadlift | D25: =IF(OR(B25="",C25=""),"",IF(C25=1,B25,ROUND(B25*(1+C25/30),1))) | F25: Under 70% | G25: 3-6 | H25: 24 | I25: 18-30
A26: Box Jump | D26: =IF(OR(B26="",C26=""),"",IF(C26=1,B26,ROUND(B26*(1+C26/30),1))) | F26: 70-80% | G26: 3-6 | H26: 18 | I26: 12-24
D27: =IF(OR(B27="",C27=""),"",IF(C27=1,B27,ROUND(B27*(1+C27/30),1))) | F27: 80-90% | G27: 2-4 | H27: 15 | I27: 10-20
D28: =IF(OR(B28="",C28=""),"",IF(C28=1,B28,ROUND(B28*(1+C28/30),1))) | F28: 90%+ | G28: 1-2 | H28: 7 | I28: 4-10
D29: =IF(OR(B29="",C29=""),"",IF(C29=1,B29,ROUND(B29*(1+C29/30),1))) | F29: Every loaded session's sets x reps come from this chart.
D30: =IF(OR(B30="",C30=""),"",IF(C30=1,B30,ROUND(B30*(1+C30/30),1)))
D31: =IF(OR(B31="",C31=""),"",IF(C31=1,B31,ROUND(B31*(1+C31/30),1))) | F31: Go to week
D32: =IF(OR(B32="",C32=""),"",IF(C32=1,B32,ROUND(B32*(1+C32/30),1))) | F32: Week 00 | G32: Week 01 | H32: Week 02 | I32: Week 03 | J32: Week 04 | K32: Week 05 | L32: Week 06 | M32: Week 07
D33: =IF(OR(B33="",C33=""),"",IF(C33=1,B33,ROUND(B33*(1+C33/30),1))) | F33: Week 08 | G33: Week 09 | H33: Week 10 | I33: Week 11 | J33: Week 12 | K33: Week 13 | L33: Week 14 | M33: Week 15
D34: =IF(OR(B34="",C34=""),"",IF(C34=1,B34,ROUND(B34*(1+C34/30),1))) | F34: Week 16 | G34: Week 17 | H34: Week 18 | I34: Week 19 | J34: Week 20 | K34: Week 21 | L34: Week 22 | M34: Week 23
D35: =IF(OR(B35="",C35=""),"",IF(C35=1,B35,ROUND(B35*(1+C35/30),1))) | F35: Week 24 | G35: Week 25 | H35: Week 26 | I35: Week 27 | J35: Week 28 | K35: Week 29 | L35: Week 30 | M35: Week 31
D36: =IF(OR(B36="",C36=""),"",IF(C36=1,B36,ROUND(B36*(1+C36/30),1))) | F36: Week 32 | G36: Week 33 | H36: Week 34 | I36: Week 35 | J36: Week 36 | K36: Week 37 | L36: Week 38 | M36: Week 39
D37: =IF(OR(B37="",C37=""),"",IF(C37=1,B37,ROUND(B37*(1+C37/30),1))) | F37: Week 40 | G37: Week 41 | H37: Week 42 | I37: Week 43 | J37: Week 44 | K37: Week 45 | L37: Week 46 | M37: Week 47
D38: =IF(OR(B38="",C38=""),"",IF(C38=1,B38,ROUND(B38*(1+C38/30),1))) | F38: Week 48 | G38: Week 49 | H38: Week 50 | I38: Week 51 | J38: Week 52
D39: =IF(OR(B39="",C39=""),"",IF(C39=1,B39,ROUND(B39*(1+C39/30),1)))
D40: =IF(OR(B40="",C40=""),"",IF(C40=1,B40,ROUND(B40*(1+C40/30),1))) | F40: How to use this workbook
...

Sheet Week 00
A1: Week 0 - Baseline test (optional)
C2: Start Here | E2: Week 01 >
A3: Bodyweight this week | C3: =IF('Start Here'!$B$9="","",'Start Here'!$B$9) | D3: Weigh in once this week: same morning routine, before eating.
A5: Day | B5: Date | C5: Exercise | D5: Sets | E5: Reps | F5: % TM | G5: Training max | H5: Weight / target | I5: Actual (weight, height or distance) | J5: Actual reps | K5: Est. 1RM | L5: PR | M5: Notes | N5: Guidance
A6: Day 1 - Heavy | B6: ='Start Here'!$B$7+-7 | C6: Box Jump | D6: 1 | E6: Max | H6: =IFERROR(IF(PRs!D69<'Start Here'!$H$15,'Start Here'!$H$15,IF(PRs!D69<'Start Here'!$H$16,'Start Here'!$H$16,IF(PRs!D69<'Start Here'!$H$17,'Start Here'!$H$17,IF(PRs!D69<'Start Here'!$H$18,'Start Here'!$H$18,"Elite!")))),"") | L6: =IF(I6="","",IF(I6>=PRs!D69,"PR!","")) | N6: Find your best: work up box by box (or jump for distance). Log it - see the standards on Start Here
A7: Day 1 - Heavy | B7: ='Start Here'!$B$7+-7 | C7: Snatch | D7: 1 | E7: 1RM | G7: =Maxes!E6 | K7: =IF(OR(I7="",J7=""),"",IF(J7=1,I7,ROUND(I7*(1+J7/30),1))) | L7: =IF(K7="","",IF(K7>=PRs!C6,"PR!","")) | N7: Optional - skip if you entered maxes. Work up to a technically clean heavy single
A8: Day 1 - Heavy | B8: ='Start Here'!$B$7+-7 | C8: Squat | D8: 1 | E8: 5RM | G8: =Maxes!E2 | K8: =IF(OR(I8="",J8=""),"",IF(J8=1,I8,ROUND(I8*(1+J8/30),1))) | L8: =IF(K8="","",IF(K8>=PRs!C2,"PR!","")) | N8: Optional - skip if you entered maxes. Work up to a hard set of 5 (or a 1RM if you're experienced)
A9: Day 1 - Heavy | B9: ='Start Here'!$B$7+-7 | C9: Bench Press | D9: 1 | E9: 5RM | G9: =Maxes!E3 | K9: =IF(OR(I9="",J9=""),"",IF(J9=1,I9,ROUND(I9*(1+J9/30),1))) | L9: =IF(K9="","",IF(K9>=PRs!C3,"PR!","")) | N9: Optional - skip if you entered maxes. Work up to a hard set of 5 (or a 1RM if you're experienced)
A10: Day 1 - Heavy | B10: ='Start Here'!$B$7+-7 | C10: Barbell Row | D10: 2 | E10: 8-10 | K10: =IF(OR(I10="",J10=""),"",IF(J10=1,I10,ROUND(I10*(1+J10/30),1))) | L10: =IF(K10="","",IF(K10>=PRs!C50,"PR!","")) | N10: Find a weight you can do for the top of the range
A11: Day 1 - Heavy | B11: ='Start Here'!$B$7+-7 | C11: Face Pull | D11: 2 | E11: 12-15 | K11: =IF(OR(I11="",J11=""),"",IF(J11=1,I11,ROUND(I11*(1+J11/30),1))) | L11: =IF(K11="","",IF(K11>=PRs!C51,"PR!","")) | N11: Find a weight you can do for the top of the range
A12: Day 2 - Light | B12: ='Start Here'!$B$7+-5 | C12: Broad Jump | D12: 1 | E12: Max | L12: =IF(I12="","",IF(I12>=PRs!D70,"PR!","")) | N12: Find your best: work up box by box (or jump for distance). Log it - see the standards on Start Here
A13: Day 2 - Light | B13: ='Start Here'!$B$7+-5 | C13: Clean & Jerk | D13: 1 | E13: 1RM | G13: =Maxes!E7 | K13: =IF(OR(I13="",J13=""),"",IF(J13=1,I13,ROUND(I13*(1+J13/30),1))) | L13: =IF(K13="","",IF(K13>=PRs!C7,"PR!","")) | N13: Optional - skip if you entered maxes. Work up to a technically clean heavy single
A14: Day 2 - Light | B14: ='Start Here'!$B$7+-5 | C14: Overhead Press | D14: 1 | E14: 5RM | G14: =Maxes!E5 | K14: =IF(OR(I14="",J14=""),"",IF(J14=1,I14,ROUND(I14*(1+J14/30),1))) | L14: =IF(K14="","",IF(K14>=PRs!C5,"PR!","")) | N14: Optional - skip if you entered maxes. Work up to a hard set of 5 (or a 1RM if you're experienced)
A15: Day 2 - Light | B15: ='Start Here'!$B$7+-5 | C15: Deadlift | D15: 1 | E15: 5RM | G15: =Maxes!E4 | K15: =IF(OR(I15="",J15=""),"",IF(J15=1,I15,ROUND(I15*(1+J15/30),1))) | L15: =IF(K15="","",IF(K15>=PRs!C4,"PR!","")) | N15: Optional - skip if you entered maxes. Work up to a hard set of 5 (or a 1RM if you're experienced)
A16: Day 2 - Light | B16: ='Start Here'!$B$7+-5 | C16: Chin-up | D16: 2 | E16: 6-10 | K16: =IF(OR(I16="",J16=""),"",IF(J16=1,I16,ROUND(I16*(1+J16/30),1))) | L16: =IF(K16="","",IF(K16>=PRs!C53,"PR!","")) | N16: Find a weight you can do for the top of the range
A17: Day 2 - Light | B17: ='Start Here'!$B$7+-5 | C17: Plank | D17: 2 | E17: 30-60s | K17: =IF(OR(I17="",J17=""),"",IF(J17=1,I17,ROUND(I17*(1+J17/30),1))) | L17: =IF(K17="","",IF(K17>=PRs!C56,"PR!","")) | N17: Find a weight you can do for the top of the range
A18: Day 3 - Variations | B18: ='Start Here'!$B$7+-3 | C18: Box Jump | D18: 1 | E18: Max | H18: =IFERROR(IF(PRs!D69<'Start Here'!$H$15,'Start Here'!$H$15,IF(PRs!D69<'Start Here'!$H$16,'Start Here'!$H$16,IF(PRs!D69<'Start Here'!$H$17,'Start Here'!$H$17,IF(PRs!D69<'Start Here'!$H$18,'Start Here'!$H$18,"Elite!")))),"") | L18: =IF(I18="","",IF(I18>=PRs!D69,"PR!","")) | N18: Find your best: work up box by box (or jump for distance). Log it - see the standards on Start Here
A19: Day 3 - Variations | B19: ='Start Here'!$B$7+-3 | C19: Power Snatch | D19: 1 | E19: 1RM | G19: =Maxes!E34 | K19: =IF(OR(I19="",J19=""),"",IF(J19=1,I19,ROUND(I19*(1+J19/30),1))) | L19: =IF(K19="","",IF(K19>=PRs!C34,"PR!","")) | N19: Optional - skip if you entered maxes. Work up to a technically clean heavy single
A20: Day 3 - Variations | B20: ='Start Here'!$B$7+-3 | C20: Box Squat | D20: 1 | E20: 5RM | G20: =Maxes!E8 | K20: =IF(OR(I20="",J20=""),"",IF(J20=1,I20,ROUND(I20*(1+J20/30),1))) | L20: =IF(K20="","",IF(K20>=PRs!C8,"PR!","")) | N20: Optional - skip if you entered maxes. Work up to a hard set of 5 (or a 1RM if you're experienced)
A21: Day 3 - Variations | B21: ='Start Here'!$B$7+-3 | C21: Close-Grip Bench Press | D21: 1 | E21: 5RM | G21: =Maxes!E14 | K21: =IF(OR(I21="",J21=""),"",IF(J21=1,I21,ROUND(I21*(1+J21/30),1))) | L21: =IF(K21="","",IF(K21>=PRs!C14,"PR!","")) | N21: Optional - skip if you entered maxes. Work up to a hard set of 5 (or a 1RM if you're experienced)
A22: Day 3 - Variations | B22: ='Start Here'!$B$7+-3 | C22: Romanian Deadlift | D22: 1 | E22: 5RM | G22: =Maxes!E23 | K22: =IF(OR(I22="",J22=""),"",IF(J22=1,I22,ROUND(I22*(1+J22/30),1))) | L22: =IF(K22="","",IF(K22>=PRs!C23,"PR!","")) | N22: Optional - skip if you entered maxes. Work up to a hard set of 5 (or a 1RM if you're experienced)
A23: Day 3 - Variations | B23: ='Start Here'!$B$7+-3 | C23: Incline Dumbbell Press | D23: 2 | E23: 8-12 | K23: =IF(OR(I23="",J23=""),"",IF(J23=1,I23,ROUND(I23*(1+J23/30),1))) | L23: =IF(K23="","",IF(K23>=PRs!C57,"PR!","")) | N23: Find a weight you can do for the top of the range
A24: Day 3 - Variations | B24: ='Start Here'!$B$7+-3 | C24: Triceps Pushdown | D24: 2 | E24: 10-15 | K24: =IF(OR(I24="",J24=""),"",IF(J24=1,I24,ROUND(I24*(1+J24/30),1))) | L24: =IF(K24="","",IF(K24>=PRs!C59,"PR!","")) | N24: Find a weight you can do for the top of the range

Sheet Week 01
A1: Week 1 - Cycle 1 - Accumulation
A2: < Week 00 | C2: Start Here | E2: Week 02 >
A3: Bodyweight this week | D3: Weigh in once this week: same morning routine, before eating.
A4: Body fat test due this week (month 1) - enter it on the Body sheet
A5: Day | B5: Date | C5: Exercise | D5: Sets | E5: Reps | F5: % TM | G5: Training max | H5: Weight / target | I5: Actual (weight, height or distance) | J5: Actual reps | K5: Est. 1RM | L5: PR | M5: Notes | N5: Guidance
A6: Day 1 - Heavy | B6: ='Start Here'!$B$7+0 | C6: Box Jump | D6: 4 | E6: 3 | H6: =IFERROR(IF(PRs!D69<'Start Here'!$H$15,'Start Here'!$H$15,IF(PRs!D69<'Start Here'!$H$16,'Start Here'!$H$16,IF(PRs!D69<'Start Here'!$H$17,'Start Here'!$H$17,IF(PRs!D69<'Start Here'!$H$18,'Start Here'!$H$18,"Elite!")))),"") | L6: =IF(I6="","",IF(I6>=PRs!D69,"PR!","")) | N6: Explode up, land softly, STEP down. Full reset between reps. Log your box height; check the standards
A7: Day 1 - Heavy | B7: ='Start Here'!$B$7+0 | C7: Snatch | D7: 4 | E7: 3 | F7: 70 | G7: =Maxes!E6 | H7: =IF(OR(G7="",F7=""),"",MROUND(G7*F7/100,'Start Here'!$B$6)) | K7: =IF(OR(I7="",J7=""),"",IF(J7=1,I7,ROUND(I7*(1+J7/30),1))) | L7: =IF(K7="","",IF(K7>=PRs!C6,"PR!",""))
A8: Day 1 - Heavy | B8: ='Start Here'!$B$7+0 | C8: Squat | D8: 3 | E8: 6 | F8: 70 | G8: =Maxes!E2 | H8: =IF(OR(G8="",F8=""),"",MROUND(G8*F8/100,'Start Here'!$B$6)) | K8: =IF(OR(I8="",J8=""),"",IF(J8=1,I8,ROUND(I8*(1+J8/30),1))) | L8: =IF(K8="","",IF(K8>=PRs!C2,"PR!",""))
A9: Day 1 - Heavy | B9: ='Start Here'!$B$7+0 | C9: Bench Press | D9: 3 | E9: 6 | F9: 70 | G9: =Maxes!E3 | H9: =IF(OR(G9="",F9=""),"",MROUND(G9*F9/100,'Start Here'!$B$6)) | K9: =IF(OR(I9="",J9=""),"",IF(J9=1,I9,ROUND(I9*(1+J9/30),1))) | L9: =IF(K9="","",IF(K9>=PRs!C3,"PR!",""))
A10: Day 1 - Heavy | B10: ='Start Here'!$B$7+0 | C10: Barbell Row | D10: 4 | E10: 8-10 | K10: =IF(OR(I10="",J10=""),"",IF(J10=1,I10,ROUND(I10*(1+J10/30),1))) | L10: =IF(K10="","",IF(K10>=PRs!C50,"PR!","")) | N10: Leave 1-2 reps in the tank; add weight when you hit the top of the range
A11: Day 1 - Heavy | B11: ='Start Here'!$B$7+0 | C11: Face Pull | D11: 4 | E11: 12-15 | K11: =IF(OR(I11="",J11=""),"",IF(J11=1,I11,ROUND(I11*(1+J11/30),1))) | L11: =IF(K11="","",IF(K11>=PRs!C51,"PR!","")) | N11: Leave 1-2 reps in the tank; add weight when you hit the top of the range
A12: Day 2 - Light | B12: ='Start Here'!$B$7+2 | C12: Broad Jump | D12: 4 | E12: 3 | L12: =IF(I12="","",IF(I12>=PRs!D70,"PR!","")) | N12: Two-foot jump for distance, stick the landing. Full reset between reps. Log your best distance
A13: Day 2 - Light | B13: ='Start Here'!$B$7+2 | C13: Clean & Jerk | D13: 4 | E13: 3 | F13: 70 | G13: =Maxes!E7 | H13: =IF(OR(G13="",F13=""),"",MROUND(G13*F13/100,'Start Here'!$B$6)) | K13: =IF(OR(I13="",J13=""),"",IF(J13=1,I13,ROUND(I13*(1+J13/30),1))) | L13: =IF(K13="","",IF(K13>=PRs!C7,"PR!",""))
A14: Day 2 - Light | B14: ='Start Here'!$B$7+2 | C14: Squat | D14: 3 | E14: 6 | F14: 60 | G14: =Maxes!E2 | H14: =IF(OR(G14="",F14=""),"",MROUND(G14*F14/100,'Start Here'!$B$6)) | K14: =IF(OR(I14="",J14=""),"",IF(J14=1,I14,ROUND(I14*(1+J14/30),1))) | L14: =IF(K14="","",IF(K14>=PRs!C2,"PR!",""))
A15: Day 2 - Light | B15: ='Start Here'!$B$7+2 | C15: Overhead Press | D15: 4 | E15: 6 | F15: 65 | G15: =Maxes!E5 | H15: =IF(OR(G15="",F15=""),"",MROUND(G15*F15/100,'Start Here'!$B$6)) | K15: =IF(OR(I15="",J15=""),"",IF(J15=1,I15,ROUND(I15*(1+J15/30),1))) | L15: =IF(K15="","",IF(K15>=PRs!C5,"PR!",""))
A16: Day 2 - Light | B16: ='Start Here'!$B$7+2 | C16: Deadlift | D16: 3 | E16: 6 | F16: 65 | G16: =Maxes!E4 | H16: =IF(OR(G16="",F16=""),"",MROUND(G16*F16/100,'Start Here'!$B$6)) | K16: =IF(OR(I16="",J16=""),"",IF(J16=1,I16,ROUND(I16*(1+J16/30),1))) | L16: =IF(K16="","",IF(K16>=PRs!C4,"PR!",""))
A17: Day 2 - Light | B17: ='Start Here'!$B$7+2 | C17: Chin-up | D17: 4 | E17: 6-10 | K17: =IF(OR(I17="",J17=""),"",IF(J17=1,I17,ROUND(I17*(1+J17/30),1))) | L17: =IF(K17="","",IF(K17>=PRs!C53,"PR!","")) | N17: Leave 1-2 reps in the tank; add weight when you hit the top of the range
A18: Day 2 - Light | B18: ='Start Here'!$B$7+2 | C18: Plank | D18: 4 | E18: 30-60s | K18: =IF(OR(I18="",J18=""),"",IF(J18=1,I18,ROUND(I18*(1+J18/30),1))) | L18: =IF(K18="","",IF(K18>=PRs!C56,"PR!","")) | N18: Leave 1-2 reps in the tank; add weight when you hit the top of the range
A19: Day 3 - Variations | B19: ='Start Here'!$B$7+4 | C19: Box Jump | D19: 4 | E19: 3 | H19: =IFERROR(IF(PRs!D69<'Start Here'!$H$15,'Start Here'!$H$15,IF(PRs!D69<'Start Here'!$H$16,'Start Here'!$H$16,IF(PRs!D69<'Start Here'!$H$17,'Start Here'!$H$17,IF(PRs!D69<'Start Here'!$H$18,'Start Here'!$H$18,"Elite!")))),"") | L19: =IF(I19="","",IF(I19>=PRs!D69,"PR!","")) | N19: Explode up, land softly, STEP down. Full reset between reps. Log your box height; check the standards
A20: Day 3 - Variations | B20: ='Start Here'!$B$7+4 | C20: Power Snatch | D20: 6 | E20: 3 | F20: 65 | G20: =Maxes!E34 | H20: =IF(OR(G20="",F20=""),"",MROUND(G20*F20/100,'Start Here'!$B$6)) | K20: =IF(OR(I20="",J20=""),"",IF(J20=1,I20,ROUND(I20*(1+J20/30),1))) | L20: =IF(K20="","",IF(K20>=PRs!C34,"PR!",""))
A21: Day 3 - Variations | B21: ='Start Here'!$B$7+4 | C21: Box Squat | D21: 4 | E21: 6 | F21: 65 | G21: =Maxes!E8 | H21: =IF(OR(G21="",F21=""),"",MROUND(G21*F21/100,'Start Here'!$B$6)) | K21: =IF(OR(I21="",J21=""),"",IF(J21=1,I21,ROUND(I21*(1+J21/30),1))) | L21: =IF(K21="","",IF(K21>=PRs!C8,"PR!",""))
A22: Day 3 - Variations | B22: ='Start Here'!$B$7+4 | C22: Close-Grip Bench Press | D22: 4 | E22: 6 | F22: 65 | G22: =Maxes!E14 | H22: =IF(OR(G22="",F22=""),"",MROUND(G22*F22/100,'Start Here'!$B$6)) | K22: =IF(OR(I22="",J22=""),"",IF(J22=1,I22,ROUND(I22*(1+J22/30),1))) | L22: =IF(K22="","",IF(K22>=PRs!C14,"PR!",""))
A23: Day 3 - Variations | B23: ='Start Here'!$B$7+4 | C23: Romanian Deadlift | D23: 3 | E23: 6 | F23: 60 | G23: =Maxes!E23 | H23: =IF(OR(G23="",F23=""),"",MROUND(G23*F23/100,'Start Here'!$B$6)) | K23: =IF(OR(I23="",J23=""),"",IF(J23=1,I23,ROUND(I23*(1+J23/30),1))) | L23: =IF(K23="","",IF(K23>=PRs!C23,"PR!",""))
A24: Day 3 - Variations | B24: ='Start Here'!$B$7+4 | C24: Incline Dumbbell Press | D24: 4 | E24: 8-12 | K24: =IF(OR(I24="",J24=""),"",IF(J24=1,I24,ROUND(I24*(1+J24/30),1))) | L24: =IF(K24="","",IF(K24>=PRs!C57,"PR!","")) | N24: Leave 1-2 reps in the tank; add weight when you hit the top of the range
A25: Day 3 - Variations | B25: ='Start Here'!$B$7+4 | C25: Triceps Pushdown | D25: 4 | E25: 10-15 | K25: =IF(OR(I25="",J25=""),"",IF(J25=1,I25,ROUND(I25*(1+J25/30),1))) | L25: =IF(K25="","",IF(K25>=PRs!C59,"PR!","")) | N25: Leave 1-2 reps in the tank; add weight when you hit the top of the range

Sheet Week 02
A1: Week 2 - Cycle 1 - Accumulation
A2: < Week 01 | C2: Start Here | E2: Week 03 >
A3: Bodyweight this week | D3: Weigh in once this week: same morning routine, before eating.
A5: Day | B5: Date | C5: Exercise | D5: Sets | E5: Reps | F5: % TM | G5: Training max | H5: Weight / target | I5: Actual (weight, height or distance) | J5: Actual reps | K5: Est. 1RM | L5: PR | M5: Notes | N5: Guidance
A6: Day 1 - Heavy | B6: ='Start Here'!$B$7+7 | C6: Box Jump | D6: 4 | E6: 3 | H6: =IFERROR(IF(PRs!D69<'Start Here'!$H$15,'Start Here'!$H$15,IF(PRs!D69<'Start Here'!$H$16,'Start Here'!$H$16,IF(PRs!D69<'Start Here'!$H$17,'Start Here'!$H$17,IF(PRs!D69<'Start Here'!$H$18,'Start Here'!$H$18,"Elite!")))),"") | L6: =IF(I6="","",IF(I6>=PRs!D69,"PR!","")) | N6: Explode up, land softly, STEP down. Full reset between reps. Log your box height; check the standards
A7: Day 1 - Heavy | B7: ='Start Here'!$B$7+7 | C7: Snatch | D7: 4 | E7: 3 | F7: 72.5 | G7: =Maxes!E6 | H7: =IF(OR(G7="",F7=""),"",MROUND(G7*F7/100,'Start Here'!$B$6)) | K7: =IF(OR(I7="",J7=""),"",IF(J7=1,I7,ROUND(I7*(1+J7/30),1))) | L7: =IF(K7="","",IF(K7>=PRs!C6,"PR!",""))
A8: Day 1 - Heavy | B8: ='Start Here'!$B$7+7 | C8: Squat | D8: 3 | E8: 6 | F8: 72.5 | G8: =Maxes!E2 | H8: =IF(OR(G8="",F8=""),"",MROUND(G8*F8/100,'Start Here'!$B$6)) | K8: =IF(OR(I8="",J8=""),"",IF(J8=1,I8,ROUND(I8*(1+J8/30),1))) | L8: =IF(K8="","",IF(K8>=PRs!C2,"PR!",""))
A9: Day 1 - Heavy | B9: ='Start Here'!$B$7+7 | C9: Bench Press | D9: 3 | E9: 6 | F9: 72.5 | G9: =Maxes!E3 | H9: =IF(OR(G9="",F9=""),"",MROUND(G9*F9/100,'Start Here'!$B$6)) | K9: =IF(OR(I9="",J9=""),"",IF(J9=1,I9,ROUND(I9*(1+J9/30),1))) | L9: =IF(K9="","",IF(K9>=PRs!C3,"PR!",""))
A10: Day 1 - Heavy | B10: ='Start Here'!$B$7+7 | C10: Barbell Row | D10: 4 | E10: 8-10 | K10: =IF(OR(I10="",J10=""),"",IF(J10=1,I10,ROUND(I10*(1+J10/30),1))) | L10: =IF(K10="","",IF(K10>=PRs!C50,"PR!","")) | N10: Leave 1-2 reps in the tank; add weight when you hit the top of the range
A11: Day 1 - Heavy | B11: ='Start Here'!$B$7+7 | C11: Face Pull | D11: 4 | E11: 12-15 | K11: =IF(OR(I11="",J11=""),"",IF(J11=1,I11,ROUND(I11*(1+J11/30),1))) | L11: =IF(K11="","",IF(K11>=PRs!C51,"PR!","")) | N11: Leave 1-2 reps in the tank; add weight when you hit the top of the range
A12: Day 2 - Light | B12: ='Start Here'!$B$7+9 | C12: Broad Jump | D12: 4 | E12: 3 | L12: =IF(I12="","",IF(I12>=PRs!D70,"PR!","")) | N12: Two-foot jump for distance, stick the landing. Full reset between reps. Log your best distance
A13: Day 2 - Light | B13: ='Start Here'!$B$7+9 | C13: Clean & Jerk | D13: 4 | E13: 3 | F13: 72.5 | G13: =Maxes!E7 | H13: =IF(OR(G13="",F13=""),"",MROUND(G13*F13/100,'Start Here'!$B$6)) | K13: =IF(OR(I13="",J13=""),"",IF(J13=1,I13,ROUND(I13*(1+J13/30),1))) | L13: =IF(K13="","",IF(K13>=PRs!C7,"PR!",""))
A14: Day 2 - Light | B14: ='Start Here'!$B$7+9 | C14: Squat | D14: 3 | E14: 6 | F14: 62.5 | G14: =Maxes!E2 | H14: =IF(OR(G14="",F14=""),"",MROUND(G14*F14/100,'Start Here'!$B$6)) | K14: =IF(OR(I14="",J14=""),"",IF(J14=1,I14,ROUND(I14*(1+J14/30),1))) | L14: =IF(K14="","",IF(K14>=PRs!C2,"PR!",""))
A15: Day 2 - Light | B15: ='Start Here'!$B$7+9 | C15: Overhead Press | D15: 4 | E15: 6 | F15: 67.5 | G15: =Maxes!E5 | H15: =IF(OR(G15="",F15=""),"",MROUND(G15*F15/100,'Start Here'!$B$6)) | K15: =IF(OR(I15="",J15=""),"",IF(J15=1,I15,ROUND(I15*(1+J15/30),1))) | L15: =IF(K15="","",IF(K15>=PRs!C5,"PR!",""))
A16: Day 2 - Light | B16: ='Start Here'!$B$7+9 | C16: Deadlift | D16: 3 | E16: 6 | F16: 67.5 | G16: =Maxes!E4 | H16: =IF(OR(G16="",F16=""),"",MROUND(G16*F16/100,'Start Here'!$B$6)) | K16: =IF(OR(I16="",J16=""),"",IF(J16=1,I16,ROUND(I16*(1+J16/30),1))) | L16: =IF(K16="","",IF(K16>=PRs!C4,"PR!",""))
A17: Day 2 - Light | B17: ='Start Here'!$B$7+9 | C17: Chin-up | D17: 4 | E17: 6-10 | K17: =IF(OR(I17="",J17=""),"",IF(J17=1,I17,ROUND(I17*(1+J17/30),1))) | L17: =IF(K17="","",IF(K17>=PRs!C53,"PR!","")) | N17: Leave 1-2 reps in the tank; add weight when you hit the top of the range
A18: Day 2 - Light | B18: ='Start Here'!$B$7+9 | C18: Plank | D18: 4 | E18: 30-60s | K18: =IF(OR(I18="",J18=""),"",IF(J18=1,I18,ROUND(I18*(1+J18/30),1))) | L18: =IF(K18="","",IF(K18>=PRs!C56,"PR!","")) | N18: Leave 1-2 reps in the tank; add weight when you hit the top of the range
A19: Day 3 - Variations | B19: ='Start Here'!$B$7+11 | C19: Box Jump | D19: 4 | E19: 3 | H19: =IFERROR(IF(PRs!D69<'Start Here'!$H$15,'Start Here'!$H$15,IF(PRs!D69<'Start Here'!$H$16,'Start Here'!$H$16,IF(PRs!D69<'Start Here'!$H$17,'Start Here'!$H$17,IF(PRs!D69<'Start Here'!$H$18,'Start Here'!$H$18,"Elite!")))),"") | L19: =IF(I19="","",IF(I19>=PRs!D69,"PR!","")) | N19: Explode up, land softly, STEP down. Full reset between reps. Log your box height; check the standards
A20: Day 3 - Variations | B20: ='Start Here'!$B$7+11 | C20: Power Snatch | D20: 6 | E20: 3 | F20: 67.5 | G20: =Maxes!E34 | H20: =IF(OR(G20="",F20=""),"",MROUND(G20*F20/100,'Start Here'!$B$6)) | K20: =IF(OR(I20="",J20=""),"",IF(J20=1,I20,ROUND(I20*(1+J20/30),1))) | L20: =IF(K20="","",IF(K20>=PRs!C34,"PR!",""))
A21: Day 3 - Variations | B21: ='Start Here'!$B$7+11 | C21: Box Squat | D21: 4 | E21: 6 | F21: 67.5 | G21: =Maxes!E8 | H21: =IF(OR(G21="",F21=""),"",MROUND(G21*F21/100,'Start Here'!$B$6)) | K21: =IF(OR(I21="",J21=""),"",IF(J21=1,I21,ROUND(I21*(1+J21/30),1))) | L21: =IF(K21="","",IF(K21>=PRs!C8,"PR!",""))
A22: Day 3 - Variations | B22: ='Start Here'!$B$7+11 | C22: Close-Grip Bench Press | D22: 4 | E22: 6 | F22: 67.5 | G22: =Maxes!E14 | H22: =IF(OR(G22="",F22=""),"",MROUND(G22*F22/100,'Start Here'!$B$6)) | K22: =IF(OR(I22="",J22=""),"",IF(J22=1,I22,ROUND(I22*(1+J22/30),1))) | L22: =IF(K22="","",IF(K22>=PRs!C14,"PR!",""))
A23: Day 3 - Variations | B23: ='Start Here'!$B$7+11 | C23: Romanian Deadlift | D23: 3 | E23: 6 | F23: 62.5 | G23: =Maxes!E23 | H23: =IF(OR(G23="",F23=""),"",MROUND(G23*F23/100,'Start Here'!$B$6)) | K23: =IF(OR(I23="",J23=""),"",IF(J23=1,I23,ROUND(I23*(1+J23/30),1))) | L23: =IF(K23="","",IF(K23>=PRs!C23,"PR!",""))
A24: Day 3 - Variations | B24: ='Start Here'!$B$7+11 | C24: Incline Dumbbell Press | D24: 4 | E24: 8-12 | K24: =IF(OR(I24="",J24=""),"",IF(J24=1,I24,ROUND(I24*(1+J24/30),1))) | L24: =IF(K24="","",IF(K24>=PRs!C57,"PR!","")) | N24: Leave 1-2 reps in the tank; add weight when you hit the top of the range
A25: Day 3 - Variations | B25: ='Start Here'!$B$7+11 | C25: Triceps Pushdown | D25: 4 | E25: 10-15 | K25: =IF(OR(I25="",J25=""),"",IF(J25=1,I25,ROUND(I25*(1+J25/30),1))) | L25: =IF(K25="","",IF(K25>=PRs!C59,"PR!","")) | N25: Leave 1-2 reps in the tank; add weight when you hit the top of the range

Sheet Week 03
A1: Week 3 - Cycle 1 - Accumulation
A2: < Week 02 | C2: Start Here | E2: Week 04 >
A3: Bodyweight this week | D3: Weigh in once this week: same morning routine, before eating.
A5: Day | B5: Date | C5: Exercise | D5: Sets | E5: Reps | F5: % TM | G5: Training max | H5: Weight / target | I5: Actual (weight, height or distance) | J5: Actual reps | K5: Est. 1RM | L5: PR | M5: Notes | N5: Guidance
A6: Day 1 - Heavy | B6: ='Start Here'!$B$7+14 | C6: Box Jump | D6: 4 | E6: 3 | H6: =IFERROR(IF(PRs!D69<'Start Here'!$H$15,'Start Here'!$H$15,IF(PRs!D69<'Start Here'!$H$16,'Start Here'!$H$16,IF(PRs!D69<'Start Here'!$H$17,'Start Here'!$H$17,IF(PRs!D69<'Start Here'!$H$18,'Start Here'!$H$18,"Elite!")))),"") | L6: =IF(I6="","",IF(I6>=PRs!D69,"PR!","")) | N6: Explode up, land softly, STEP down. Full reset between reps. Log your box height; check the standards
A7: Day 1 - Heavy | B7: ='Start Here'!$B$7+14 | C7: Snatch | D7: 4 | E7: 3 | F7: 75 | G7: =Maxes!E6 | H7: =IF(OR(G7="",F7=""),"",MROUND(G7*F7/100,'Start Here'!$B$6)) | K7: =IF(OR(I7="",J7=""),"",IF(J7=1,I7,ROUND(I7*(1+J7/30),1))) | L7: =IF(K7="","",IF(K7>=PRs!C6,"PR!",""))
A8: Day 1 - Heavy | B8: ='Start Here'!$B$7+14 | C8: Squat | D8: 3 | E8: 6 | F8: 75 | G8: =Maxes!E2 | H8: =IF(OR(G8="",F8=""),"",MROUND(G8*F8/100,'Start Here'!$B$6)) | K8: =IF(OR(I8="",J8=""),"",IF(J8=1,I8,ROUND(I8*(1+J8/30),1))) | L8: =IF(K8="","",IF(K8>=PRs!C2,"PR!",""))
A9: Day 1 - Heavy | B9: ='Start Here'!$B$7+14 | C9: Bench Press | D9: 3 | E9: 6 | F9: 75 | G9: =Maxes!E3 | H9: =IF(OR(G9="",F9=""),"",MROUND(G9*F9/100,'Start Here'!$B$6)) | K9: =IF(OR(I9="",J9=""),"",IF(J9=1,I9,ROUND(I9*(1+J9/30),1))) | L9: =IF(K9="","",IF(K9>=PRs!C3,"PR!",""))
A10: Day 1 - Heavy | B10: ='Start Here'!$B$7+14 | C10: Barbell Row | D10: 4 | E10: 8-10 | K10: =IF(OR(I10="",J10=""),"",IF(J10=1,I10,ROUND(I10*(1+J10/30),1))) | L10: =IF(K10="","",IF(K10>=PRs!C50,"PR!","")) | N10: Leave 1-2 reps in the tank; add weight when you hit the top of the range
A11: Day 1 - Heavy | B11: ='Start Here'!$B$7+14 | C11: Face Pull | D11: 4 | E11: 12-15 | K11: =IF(OR(I11="",J11=""),"",IF(J11=1,I11,ROUND(I11*(1+J11/30),1))) | L11: =IF(K11="","",IF(K11>=PRs!C51,"PR!","")) | N11: Leave 1-2 reps in the tank; add weight when you hit the top of the range
A12: Day 2 - Light | B12: ='Start Here'!$B$7+16 | C12: Broad Jump | D12: 4 | E12: 3 | L12: =IF(I12="","",IF(I12>=PRs!D70,"PR!","")) | N12: Two-foot jump for distance, stick the landing. Full reset between reps. Log your best distance
A13: Day 2 - Light | B13: ='Start Here'!$B$7+16 | C13: Clean & Jerk | D13: 4 | E13: 3 | F13: 75 | G13: =Maxes!E7 | H13: =IF(OR(G13="",F13=""),"",MROUND(G13*F13/100,'Start Here'!$B$6)) | K13: =IF(OR(I13="",J13=""),"",IF(J13=1,I13,ROUND(I13*(1+J13/30),1))) | L13: =IF(K13="","",IF(K13>=PRs!C7,"PR!",""))
A14: Day 2 - Light | B14: ='Start Here'!$B$7+16 | C14: Squat | D14: 3 | E14: 6 | F14: 65 | G14: =Maxes!E2 | H14: =IF(OR(G14="",F14=""),"",MROUND(G14*F14/100,'Start Here'!$B$6)) | K14: =IF(OR(I14="",J14=""),"",IF(J14=1,I14,ROUND(I14*(1+J14/30),1))) | L14: =IF(K14="","",IF(K14>=PRs!C2,"PR!",""))
A15: Day 2 - Light | B15: ='Start Here'!$B$7+16 | C15: Overhead Press | D15: 3 | E15: 6 | F15: 70 | G15: =Maxes!E5 | H15: =IF(OR(G15="",F15=""),"",MROUND(G15*F15/100,'Start Here'!$B$6)) | K15: =IF(OR(I15="",J15=""),"",IF(J15=1,I15,ROUND(I15*(1+J15/30),1))) | L15: =IF(K15="","",IF(K15>=PRs!C5,"PR!",""))
A16: Day 2 - Light | B16: ='Start Here'!$B$7+16 | C16: Deadlift | D16: 3 | E16: 6 | F16: 70 | G16: =Maxes!E4 | H16: =IF(OR(G16="",F16=""),"",MROUND(G16*F16/100,'Start Here'!$B$6)) | K16: =IF(OR(I16="",J16=""),"",IF(J16=1,I16,ROUND(I16*(1+J16/30),1))) | L16: =IF(K16="","",IF(K16>=PRs!C4,"PR!",""))
A17: Day 2 - Light | B17: ='Start Here'!$B$7+16 | C17: Chin-up | D17: 4 | E17: 6-10 | K17: =IF(OR(I17="",J17=""),"",IF(J17=1,I17,ROUND(I17*(1+J17/30),1))) | L17: =IF(K17="","",IF(K17>=PRs!C53,"PR!","")) | N17: Leave 1-2 reps in the tank; add weight when you hit the top of the range
A18: Day 2 - Light | B18: ='Start Here'!$B$7+16 | C18: Plank | D18: 4 | E18: 30-60s | K18: =IF(OR(I18="",J18=""),"",IF(J18=1,I18,ROUND(I18*(1+J18/30),1))) | L18: =IF(K18="","",IF(K18>=PRs!C56,"PR!","")) | N18: Leave 1-2 reps in the tank; add weight when you hit the top of the range
A19: Day 3 - Variations | B19: ='Start Here'!$B$7+18 | C19: Box Jump | D19: 4 | E19: 3 | H19: =IFERROR(IF(PRs!D69<'Start Here'!$H$15,'Start Here'!$H$15,IF(PRs!D69<'Start Here'!$H$16,'Start Here'!$H$16,IF(PRs!D69<'Start Here'!$H$17,'Start Here'!$H$17,IF(PRs!D69<'Start Here'!$H$18,'Start Here'!$H$18,"Elite!")))),"") | L19: =IF(I19="","",IF(I19>=PRs!D69,"PR!","")) | N19: Explode up, land softly, STEP down. Full reset between reps. Log your box height; check the standards
A20: Day 3 - Variations | B20: ='Start Here'!$B$7+18 | C20: Power Snatch | D20: 4 | E20: 3 | F20: 70 | G20: =Maxes!E34 | H20: =IF(OR(G20="",F20=""),"",MROUND(G20*F20/100,'Start Here'!$B$6)) | K20: =IF(OR(I20="",J20=""),"",IF(J20=1,I20,ROUND(I20*(1+J20/30),1))) | L20: =IF(K20="","",IF(K20>=PRs!C34,"PR!",""))
A21: Day 3 - Variations | B21: ='Start Here'!$B$7+18 | C21: Box Squat | D21: 3 | E21: 6 | F21: 70 | G21: =Maxes!E8 | H21: =IF(OR(G21="",F21=""),"",MROUND(G21*F21/100,'Start Here'!$B$6)) | K21: =IF(OR(I21="",J21=""),"",IF(J21=1,I21,ROUND(I21*(1+J21/30),1))) | L21: =IF(K21="","",IF(K21>=PRs!C8,"PR!",""))
A22: Day 3 - Variations | B22: ='Start Here'!$B$7+18 | C22: Close-Grip Bench Press | D22: 3 | E22: 6 | F22: 70 | G22: =Maxes!E14 | H22: =IF(OR(G22="",F22=""),"",MROUND(G22*F22/100,'Start Here'!$B$6)) | K22: =IF(OR(I22="",J22=""),"",IF(J22=1,I22,ROUND(I22*(1+J22/30),1))) | L22: =IF(K22="","",IF(K22>=PRs!C14,"PR!",""))
A23: Day 3 - Variations | B23: ='Start Here'!$B$7+18 | C23: Romanian Deadlift | D23: 3 | E23: 6 | F23: 65 | G23: =Maxes!E23 | H23: =IF(OR(G23="",F23=""),"",MROUND(G23*F23/100,'Start Here'!$B$6)) | K23: =IF(OR(I23="",J23=""),"",IF(J23=1,I23,ROUND(I23*(1+J23/30),1))) | L23: =IF(K23="","",IF(K23>=PRs!C23,"PR!",""))
A24: Day 3 - Variations | B24: ='Start Here'!$B$7+18 | C24: Incline Dumbbell Press | D24: 4 | E24: 8-12 | K24: =IF(OR(I24="",J24=""),"",IF(J24=1,I24,ROUND(I24*(1+J24/30),1))) | L24: =IF(K24="","",IF(K24>=PRs!C57,"PR!","")) | N24: Leave 1-2 reps in the tank; add weight when you hit the top of the range
A25: Day 3 - Variations | B25: ='Start Here'!$B$7+18 | C25: Triceps Pushdown | D25: 4 | E25: 10-15 | K25: =IF(OR(I25="",J25=""),"",IF(J25=1,I25,ROUND(I25*(1+J25/30),1))) | L25: =IF(K25="","",IF(K25>=PRs!C59,"PR!","")) | N25: Leave 1-2 reps in the tank; add weight when you hit the top of the range

Sheet Week 04
A1: Week 4 - Cycle 1 - Deload
A2: < Week 03 | C2: Start Here | E2: Week 05 >
A3: Bodyweight this week | D3: Weigh in once this week: same morning routine, before eating.
A5: Day | B5: Date | C5: Exercise | D5: Sets | E5: Reps | F5: % TM | G5: Training max | H5: Weight / target | I5: Actual (weight, height or distance) | J5: Actual reps | K5: Est. 1RM | L5: PR | M5: Notes | N5: Guidance
A6: Day 1 - Heavy | B6: ='Start Here'!$B$7+21 | C6: Box Jump | D6: 2 | E6: 3 | H6: =IFERROR(IF(PRs!D69<'Start Here'!$H$15,'Start Here'!$H$15,IF(PRs!D69<'Start Here'!$H$16,'Start Here'!$H$16,IF(PRs!D69<'Start Here'!$H$17,'Start Here'!$H$17,IF(PRs!D69<'Start Here'!$H$18,'Start Here'!$H$18,"Elite!")))),"") | L6: =IF(I6="","",IF(I6>=PRs!D69,"PR!","")) | N6: Explode up, land softly, STEP down. Full reset between reps. Log your box height; check the standards
A7: Day 1 - Heavy | B7: ='Start Here'!$B$7+21 | C7: Snatch | D7: 2 | E7: 2 | F7: 60 | G7: =Maxes!E6 | H7: =IF(OR(G7="",F7=""),"",MROUND(G7*F7/100,'Start Here'!$B$6)) | K7: =IF(OR(I7="",J7=""),"",IF(J7=1,I7,ROUND(I7*(1+J7/30),1))) | L7: =IF(K7="","",IF(K7>=PRs!C6,"PR!","")) | N7: Easy week - move fast, recover
A8: Day 1 - Heavy | B8: ='Start Here'!$B$7+21 | C8: Squat | D8: 2 | E8: 5 | F8: 60 | G8: =Maxes!E2 | H8: =IF(OR(G8="",F8=""),"",MROUND(G8*F8/100,'Start Here'!$B$6)) | K8: =IF(OR(I8="",J8=""),"",IF(J8=1,I8,ROUND(I8*(1+J8/30),1))) | L8: =IF(K8="","",IF(K8>=PRs!C2,"PR!","")) | N8: Easy week - move fast, recover
A9: Day 1 - Heavy | B9: ='Start Here'!$B$7+21 | C9: Bench Press | D9: 2 | E9: 5 | F9: 60 | G9: =Maxes!E3 | H9: =IF(OR(G9="",F9=""),"",MROUND(G9*F9/100,'Start Here'!$B$6)) | K9: =IF(OR(I9="",J9=""),"",IF(J9=1,I9,ROUND(I9*(1+J9/30),1))) | L9: =IF(K9="","",IF(K9>=PRs!C3,"PR!","")) | N9: Easy week - move fast, recover
A10: Day 1 - Heavy | B10: ='Start Here'!$B$7+21 | C10: Barbell Row | D10: 2 | E10: 8-10 | K10: =IF(OR(I10="",J10=""),"",IF(J10=1,I10,ROUND(I10*(1+J10/30),1))) | L10: =IF(K10="","",IF(K10>=PRs!C50,"PR!","")) | N10: Easy - stop well short of failure
A11: Day 1 - Heavy | B11: ='Start Here'!$B$7+21 | C11: Face Pull | D11: 2 | E11: 12-15 | K11: =IF(OR(I11="",J11=""),"",IF(J11=1,I11,ROUND(I11*(1+J11/30),1))) | L11: =IF(K11="","",IF(K11>=PRs!C51,"PR!","")) | N11: Easy - stop well short of failure
A12: Day 2 - Light | B12: ='Start Here'!$B$7+23 | C12: Broad Jump | D12: 2 | E12: 3 | L12: =IF(I12="","",IF(I12>=PRs!D70,"PR!","")) | N12: Two-foot jump for distance, stick the landing. Full reset between reps. Log your best distance
A13: Day 2 - Light | B13: ='Start Here'!$B$7+23 | C13: Clean & Jerk | D13: 2 | E13: 2 | F13: 60 | G13: =Maxes!E7 | H13: =IF(OR(G13="",F13=""),"",MROUND(G13*F13/100,'Start Here'!$B$6)) | K13: =IF(OR(I13="",J13=""),"",IF(J13=1,I13,ROUND(I13*(1+J13/30),1))) | L13: =IF(K13="","",IF(K13>=PRs!C7,"PR!","")) | N13: Easy week - move fast, recover
A14: Day 2 - Light | B14: ='Start Here'!$B$7+23 | C14: Squat | D14: 2 | E14: 5 | F14: 60 | G14: =Maxes!E2 | H14: =IF(OR(G14="",F14=""),"",MROUND(G14*F14/100,'Start Here'!$B$6)) | K14: =IF(OR(I14="",J14=""),"",IF(J14=1,I14,ROUND(I14*(1+J14/30),1))) | L14: =IF(K14="","",IF(K14>=PRs!C2,"PR!","")) | N14: Easy week - move fast, recover
A15: Day 2 - Light | B15: ='Start Here'!$B$7+23 | C15: Overhead Press | D15: 2 | E15: 5 | F15: 60 | G15: =Maxes!E5 | H15: =IF(OR(G15="",F15=""),"",MROUND(G15*F15/100,'Start Here'!$B$6)) | K15: =IF(OR(I15="",J15=""),"",IF(J15=1,I15,ROUND(I15*(1+J15/30),1))) | L15: =IF(K15="","",IF(K15>=PRs!C5,"PR!","")) | N15: Easy week - move fast, recover
A16: Day 2 - Light | B16: ='Start Here'!$B$7+23 | C16: Deadlift | D16: 2 | E16: 5 | F16: 60 | G16: =Maxes!E4 | H16: =IF(OR(G16="",F16=""),"",MROUND(G16*F16/100,'Start Here'!$B$6)) | K16: =IF(OR(I16="",J16=""),"",IF(J16=1,I16,ROUND(I16*(1+J16/30),1))) | L16: =IF(K16="","",IF(K16>=PRs!C4,"PR!","")) | N16: Easy week - move fast, recover
A17: Day 2 - Light | B17: ='Start Here'!$B$7+23 | C17: Chin-up | D17: 2 | E17: 6-10 | K17: =IF(OR(I17="",J17=""),"",IF(J17=1,I17,ROUND(I17*(1+J17/30),1))) | L17: =IF(K17="","",IF(K17>=PRs!C53,"PR!","")) | N17: Easy - stop well short of failure
A18: Day 2 - Light | B18: ='Start Here'!$B$7+23 | C18: Plank | D18: 2 | E18: 30-60s | K18: =IF(OR(I18="",J18=""),"",IF(J18=1,I18,ROUND(I18*(1+J18/30),1))) | L18: =IF(K18="","",IF(K18>=PRs!C56,"PR!","")) | N18: Easy - stop well short of failure
A19: Day 3 - Variations | B19: ='Start Here'!$B$7+25 | C19: Box Jump | D19: 2 | E19: 3 | H19: =IFERROR(IF(PRs!D69<'Start Here'!$H$15,'Start Here'!$H$15,IF(PRs!D69<'Start Here'!$H$16,'Start Here'!$H$16,IF(PRs!D69<'Start Here'!$H$17,'Start Here'!$H$17,IF(PRs!D69<'Start Here'!$H$18,'Start Here'!$H$18,"Elite!")))),"") | L19: =IF(I19="","",IF(I19>=PRs!D69,"PR!","")) | N19: Explode up, land softly, STEP down. Full reset between reps. Log your box height; check the standards
A20: Day 3 - Variations | B20: ='Start Here'!$B$7+25 | C20: Power Snatch | D20: 2 | E20: 2 | F20: 60 | G20: =Maxes!E34 | H20: =IF(OR(G20="",F20=""),"",MROUND(G20*F20/100,'Start Here'!$B$6)) | K20: =IF(OR(I20="",J20=""),"",IF(J20=1,I20,ROUND(I20*(1+J20/30),1))) | L20: =IF(K20="","",IF(K20>=PRs!C34,"PR!","")) | N20: Easy week - move fast, recover
A21: Day 3 - Variations | B21: ='Start Here'!$B$7+25 | C21: Box Squat | D21: 2 | E21: 5 | F21: 60 | G21: =Maxes!E8 | H21: =IF(OR(G21="",F21=""),"",MROUND(G21*F21/100,'Start Here'!$B$6)) | K21: =IF(OR(I21="",J21=""),"",IF(J21=1,I21,ROUND(I21*(1+J21/30),1))) | L21: =IF(K21="","",IF(K21>=PRs!C8,"PR!","")) | N21: Easy week - move fast, recover
A22: Day 3 - Variations | B22: ='Start Here'!$B$7+25 | C22: Close-Grip Bench Press | D22: 2 | E22: 5 | F22: 60 | G22: =Maxes!E14 | H22: =IF(OR(G22="",F22=""),"",MROUND(G22*F22/100,'Start Here'!$B$6)) | K22: =IF(OR(I22="",J22=""),"",IF(J22=1,I22,ROUND(I22*(1+J22/30),1))) | L22: =IF(K22="","",IF(K22>=PRs!C14,"PR!","")) | N22: Easy week - move fast, recover
A23: Day 3 - Variations | B23: ='Start Here'!$B$7+25 | C23: Romanian Deadlift | D23: 2 | E23: 5 | F23: 60 | G23: =Maxes!E23 | H23: =IF(OR(G23="",F23=""),"",MROUND(G23*F23/100,'Start Here'!$B$6)) | K23: =IF(OR(I23="",J23=""),"",IF(J23=1,I23,ROUND(I23*(1+J23/30),1))) | L23: =IF(K23="","",IF(K23>=PRs!C23,"PR!","")) | N23: Easy week - move fast, recover
A24: Day 3 - Variations | B24: ='Start Here'!$B$7+25 | C24: Incline Dumbbell Press | D24: 2 | E24: 8-12 | K24: =IF(OR(I24="",J24=""),"",IF(J24=1,I24,ROUND(I24*(1+J24/30),1))) | L24: =IF(K24="","",IF(K24>=PRs!C57,"PR!","")) | N24: Easy - stop well short of failure
A25: Day 3 - Variations | B25: ='Start Here'!$B$7+25 | C25: Triceps Pushdown | D25: 2 | E25: 10-15 | K25: =IF(OR(I25="",J25=""),"",IF(J25=1,I25,ROUND(I25*(1+J25/30),1))) | L25: =IF(K25="","",IF(K25>=PRs!C59,"PR!","")) | N25: Easy - stop well short of failure

Sheet Week 05
A1: Week 5 - Cycle 1 - Transmutation
A2: < Week 04 | C2: Start Here | E2: Week 06 >
A3: Bodyweight this week | D3: Weigh in once this week: same morning routine, before eating.
A4: Body fat test due this week (month 2) - enter it on the Body sheet
A5: Day | B5: Date | C5: Exercise | D5: Sets | E5: Reps | F5: % TM | G5: Training max | H5: Weight / target | I5: Actual (weight, height or distance) | J5: Actual reps | K5: Est. 1RM | L5: PR | M5: Notes | N5: Guidance
A6: Day 1 - Heavy | B6: ='Start Here'!$B$7+28 | C6: Box Jump | D6: 4 | E6: 3 | H6: =IFERROR(IF(PRs!D69<'Start Here'!$H$15,'Start Here'!$H$15,IF(PRs!D69<'Start Here'!$H$16,'Start Here'!$H$16,IF(PRs!D69<'Start Here'!$H$17,'Start Here'!$H$17,IF(PRs!D69<'Start Here'!$H$18,'Start Here'!$H$18,"Elite!")))),"") | L6: =IF(I6="","",IF(I6>=PRs!D69,"PR!","")) | N6: Explode up, land softly, STEP down. Full reset between reps. Log your box height; check the standards
A7: Day 1 - Heavy | B7: ='Start Here'!$B$7+28 | C7: Snatch | D7: 4 | E7: 3 | F7: 77.5 | G7: =Maxes!E6 | H7: =IF(OR(G7="",F7=""),"",MROUND(G7*F7/100,'Start Here'!$B$6)) | K7: =IF(OR(I7="",J7=""),"",IF(J7=1,I7,ROUND(I7*(1+J7/30),1))) | L7: =IF(K7="","",IF(K7>=PRs!C6,"PR!",""))
A8: Day 1 - Heavy | B8: ='Start Here'!$B$7+28 | C8: Squat | D8: 3 | E8: 6 | F8: 77.5 | G8: =Maxes!E2 | H8: =IF(OR(G8="",F8=""),"",MROUND(G8*F8/100,'Start Here'!$B$6)) | K8: =IF(OR(I8="",J8=""),"",IF(J8=1,I8,ROUND(I8*(1+J8/30),1))) | L8: =IF(K8="","",IF(K8>=PRs!C2,"PR!",""))
A9: Day 1 - Heavy | B9: ='Start Here'!$B$7+28 | C9: Bench Press | D9: 3 | E9: 6 | F9: 77.5 | G9: =Maxes!E3 | H9: =IF(OR(G9="",F9=""),"",MROUND(G9*F9/100,'Start Here'!$B$6)) | K9: =IF(OR(I9="",J9=""),"",IF(J9=1,I9,ROUND(I9*(1+J9/30),1))) | L9: =IF(K9="","",IF(K9>=PRs!C3,"PR!",""))
A10: Day 1 - Heavy | B10: ='Start Here'!$B$7+28 | C10: Barbell Row | D10: 3 | E10: 8-10 | K10: =IF(OR(I10="",J10=""),"",IF(J10=1,I10,ROUND(I10*(1+J10/30),1))) | L10: =IF(K10="","",IF(K10>=PRs!C50,"PR!","")) | N10: Leave 1-2 reps in the tank; add weight when you hit the top of the range
A11: Day 1 - Heavy | B11: ='Start Here'!$B$7+28 | C11: Face Pull | D11: 3 | E11: 12-15 | K11: =IF(OR(I11="",J11=""),"",IF(J11=1,I11,ROUND(I11*(1+J11/30),1))) | L11: =IF(K11="","",IF(K11>=PRs!C51,"PR!","")) | N11: Leave 1-2 reps in the tank; add weight when you hit the top of the range
A12: Day 2 - Light | B12: ='Start Here'!$B$7+30 | C12: Broad Jump | D12: 4 | E12: 3 | L12: =IF(I12="","",IF(I12>=PRs!D70,"PR!","")) | N12: Two-foot jump for distance, stick the landing. Full reset between reps. Log your best distance
A13: Day 2 - Light | B13: ='Start Here'!$B$7+30 | C13: Clean & Jerk | D13: 4 | E13: 3 | F13: 77.5 | G13: =Maxes!E7 | H13: =IF(OR(G13="",F13=""),"",MROUND(G13*F13/100,'Start Here'!$B$6)) | K13: =IF(OR(I13="",J13=""),"",IF(J13=1,I13,ROUND(I13*(1+J13/30),1))) | L13: =IF(K13="","",IF(K13>=PRs!C7,"PR!",""))
A14: Day 2 - Light | B14: ='Start Here'!$B$7+30 | C14: Squat | D14: 3 | E14: 6 | F14: 65 | G14: =Maxes!E2 | H14: =IF(OR(G14="",F14=""),"",MROUND(G14*F14/100,'Start Here'!$B$6)) | K14: =IF(OR(I14="",J14=""),"",IF(J14=1,I14,ROUND(I14*(1+J14/30),1))) | L14: =IF(K14="","",IF(K14>=PRs!C2,"PR!",""))
A15: Day 2 - Light | B15: ='Start Here'!$B$7+30 | C15: Overhead Press | D15: 3 | E15: 6 | F15: 72.5 | G15: =Maxes!E5 | H15: =IF(OR(G15="",F15=""),"",MROUND(G15*F15/100,'Start Here'!$B$6)) | K15: =IF(OR(I15="",J15=""),"",IF(J15=1,I15,ROUND(I15*(1+J15/30),1))) | L15: =IF(K15="","",IF(K15>=PRs!C5,"PR!",""))
A16: Day 2 - Light | B16: ='Start Here'!$B$7+30 | C16: Deadlift | D16: 3 | E16: 6 | F16: 72.5 | G16: =Maxes!E4 | H16: =IF(OR(G16="",F16=""),"",MROUND(G16*F16/100,'Start Here'!$B$6)) | K16: =IF(OR(I16="",J16=""),"",IF(J16=1,I16,ROUND(I16*(1+J16/30),1))) | L16: =IF(K16="","",IF(K16>=PRs!C4,"PR!",""))
A17: Day 2 - Light | B17: ='Start Here'!$B$7+30 | C17: Chin-up | D17: 3 | E17: 6-10 | K17: =IF(OR(I17="",J17=""),"",IF(J17=1,I17,ROUND(I17*(1+J17/30),1))) | L17: =IF(K17="","",IF(K17>=PRs!C53,"PR!","")) | N17: Leave 1-2 reps in the tank; add weight when you hit the top of the range
A18: Day 2 - Light | B18: ='Start Here'!$B$7+30 | C18: Plank | D18: 3 | E18: 30-60s | K18: =IF(OR(I18="",J18=""),"",IF(J18=1,I18,ROUND(I18*(1+J18/30),1))) | L18: =IF(K18="","",IF(K18>=PRs!C56,"PR!","")) | N18: Leave 1-2 reps in the tank; add weight when you hit the top of the range
A19: Day 3 - Variations | B19: ='Start Here'!$B$7+32 | C19: Box Jump | D19: 4 | E19: 3 | H19: =IFERROR(IF(PRs!D69<'Start Here'!$H$15,'Start Here'!$H$15,IF(PRs!D69<'Start Here'!$H$16,'Start Here'!$H$16,IF(PRs!D69<'Start Here'!$H$17,'Start Here'!$H$17,IF(PRs!D69<'Start Here'!$H$18,'Start Here'!$H$18,"Elite!")))),"") | L19: =IF(I19="","",IF(I19>=PRs!D69,"PR!","")) | N19: Explode up, land softly, STEP down. Full reset between reps. Log your box height; check the standards
A20: Day 3 - Variations | B20: ='Start Here'!$B$7+32 | C20: Power Clean | D20: 4 | E20: 3 | F20: 72.5 | G20: =Maxes!E42 | H20: =IF(OR(G20="",F20=""),"",MROUND(G20*F20/100,'Start Here'!$B$6)) | K20: =IF(OR(I20="",J20=""),"",IF(J20=1,I20,ROUND(I20*(1+J20/30),1))) | L20: =IF(K20="","",IF(K20>=PRs!C42,"PR!",""))
A21: Day 3 - Variations | B21: ='Start Here'!$B$7+32 | C21: Pause Squat | D21: 3 | E21: 6 | F21: 72.5 | G21: =Maxes!E9 | H21: =IF(OR(G21="",F21=""),"",MROUND(G21*F21/100,'Start Here'!$B$6)) | K21: =IF(OR(I21="",J21=""),"",IF(J21=1,I21,ROUND(I21*(1+J21/30),1))) | L21: =IF(K21="","",IF(K21>=PRs!C9,"PR!",""))
A22: Day 3 - Variations | B22: ='Start Here'!$B$7+32 | C22: 2-Board Press | D22: 3 | E22: 6 | F22: 72.5 | G22: =Maxes!E16 | H22: =IF(OR(G22="",F22=""),"",MROUND(G22*F22/100,'Start Here'!$B$6)) | K22: =IF(OR(I22="",J22=""),"",IF(J22=1,I22,ROUND(I22*(1+J22/30),1))) | L22: =IF(K22="","",IF(K22>=PRs!C16,"PR!",""))
A23: Day 3 - Variations | B23: ='Start Here'!$B$7+32 | C23: Deficit Deadlift | D23: 3 | E23: 6 | F23: 65 | G23: =Maxes!E24 | H23: =IF(OR(G23="",F23=""),"",MROUND(G23*F23/100,'Start Here'!$B$6)) | K23: =IF(OR(I23="",J23=""),"",IF(J23=1,I23,ROUND(I23*(1+J23/30),1))) | L23: =IF(K23="","",IF(K23>=PRs!C24,"PR!",""))
A24: Day 3 - Variations | B24: ='Start Here'!$B$7+32 | C24: Incline Dumbbell Press | D24: 3 | E24: 8-12 | K24: =IF(OR(I24="",J24=""),"",IF(J24=1,I24,ROUND(I24*(1+J24/30),1))) | L24: =IF(K24="","",IF(K24>=PRs!C57,"PR!","")) | N24: Leave 1-2 reps in the tank; add weight when you hit the top of the range
A25: Day 3 - Variations | B25: ='Start Here'!$B$7+32 | C25: Triceps Pushdown | D25: 3 | E25: 10-15 | K25: =IF(OR(I25="",J25=""),"",IF(J25=1,I25,ROUND(I25*(1+J25/30),1))) | L25: =IF(K25="","",IF(K25>=PRs!C59,"PR!","")) | N25: Leave 1-2 reps in the tank; add weight when you hit the top of the range

Sheet Week 06
A1: Week 6 - Cycle 1 - Transmutation
A2: < Week 05 | C2: Start Here | E2: Week 07 >
A3: Bodyweight this week | D3: Weigh in once this week: same morning routine, before eating.
A5: Day | B5: Date | C5: Exercise | D5: Sets | E5: Reps | F5: % TM | G5: Training max | H5: Weight / target | I5: Actual (weight, height or distance) | J5: Actual reps | K5: Est. 1RM | L5: PR | M5: Notes | N5: Guidance
A6: Day 1 - Heavy | B6: ='Start Here'!$B$7+35 | C6: Box Jump | D6: 4 | E6: 3 | H6: =IFERROR(IF(PRs!D69<'Start Here'!$H$15,'Start Here'!$H$15,IF(PRs!D69<'Start Here'!$H$16,'Start Here'!$H$16,IF(PRs!D69<'Start Here'!$H$17,'Start Here'!$H$17,IF(PRs!D69<'Start Here'!$H$18,'Start Here'!$H$18,"Elite!")))),"") | L6: =IF(I6="","",IF(I6>=PRs!D69,"PR!","")) | N6: Explode up, land softly, STEP down. Full reset between reps. Log your box height; check the standards
A7: Day 1 - Heavy | B7: ='Start Here'!$B$7+35 | C7: Snatch | D7: 5 | E7: 2 | F7: 80 | G7: =Maxes!E6 | H7: =IF(OR(G7="",F7=""),"",MROUND(G7*F7/100,'Start Here'!$B$6)) | K7: =IF(OR(I7="",J7=""),"",IF(J7=1,I7,ROUND(I7*(1+J7/30),1))) | L7: =IF(K7="","",IF(K7>=PRs!C6,"PR!",""))
A8: Day 1 - Heavy | B8: ='Start Here'!$B$7+35 | C8: Squat | D8: 4 | E8: 4 | F8: 80 | G8: =Maxes!E2 | H8: =IF(OR(G8="",F8=""),"",MROUND(G8*F8/100,'Start Here'!$B$6)) | K8: =IF(OR(I8="",J8=""),"",IF(J8=1,I8,ROUND(I8*(1+J8/30),1))) | L8: =IF(K8="","",IF(K8>=PRs!C2,"PR!",""))
A9: Day 1 - Heavy | B9: ='Start Here'!$B$7+35 | C9: Bench Press | D9: 4 | E9: 4 | F9: 80 | G9: =Maxes!E3 | H9: =IF(OR(G9="",F9=""),"",MROUND(G9*F9/100,'Start Here'!$B$6)) | K9: =IF(OR(I9="",J9=""),"",IF(J9=1,I9,ROUND(I9*(1+J9/30),1))) | L9: =IF(K9="","",IF(K9>=PRs!C3,"PR!",""))
A10: Day 1 - Heavy | B10: ='Start Here'!$B$7+35 | C10: Barbell Row | D10: 3 | E10: 8-10 | K10: =IF(OR(I10="",J10=""),"",IF(J10=1,I10,ROUND(I10*(1+J10/30),1))) | L10: =IF(K10="","",IF(K10>=PRs!C50,"PR!","")) | N10: Leave 1-2 reps in the tank; add weight when you hit the top of the range
A11: Day 1 - Heavy | B11: ='Start Here'!$B$7+35 | C11: Face Pull | D11: 3 | E11: 12-15 | K11: =IF(OR(I11="",J11=""),"",IF(J11=1,I11,ROUND(I11*(1+J11/30),1))) | L11: =IF(K11="","",IF(K11>=PRs!C51,"PR!","")) | N11: Leave 1-2 reps in the tank; add weight when you hit the top of the range
A12: Day 2 - Light | B12: ='Start Here'!$B$7+37 | C12: Broad Jump | D12: 4 | E12: 3 | L12: =IF(I12="","",IF(I12>=PRs!D70,"PR!","")) | N12: Two-foot jump for distance, stick the landing. Full reset between reps. Log your best distance
A13: Day 2 - Light | B13: ='Start Here'!$B$7+37 | C13: Clean & Jerk | D13: 5 | E13: 2 | F13: 80 | G13: =Maxes!E7 | H13: =IF(OR(G13="",F13=""),"",MROUND(G13*F13/100,'Start Here'!$B$6)) | K13: =IF(OR(I13="",J13=""),"",IF(J13=1,I13,ROUND(I13*(1+J13/30),1))) | L13: =IF(K13="","",IF(K13>=PRs!C7,"PR!",""))
A14: Day 2 - Light | B14: ='Start Here'!$B$7+37 | C14: Squat | D14: 3 | E14: 6 | F14: 67.5 | G14: =Maxes!E2 | H14: =IF(OR(G14="",F14=""),"",MROUND(G14*F14/100,'Start Here'!$B$6)) | K14: =IF(OR(I14="",J14=""),"",IF(J14=1,I14,ROUND(I14*(1+J14/30),1))) | L14: =IF(K14="","",IF(K14>=PRs!C2,"PR!",""))
A15: Day 2 - Light | B15: ='Start Here'!$B$7+37 | C15: Overhead Press | D15: 3 | E15: 6 | F15: 75 | G15: =Maxes!E5 | H15: =IF(OR(G15="",F15=""),"",MROUND(G15*F15/100,'Start Here'!$B$6)) | K15: =IF(OR(I15="",J15=""),"",IF(J15=1,I15,ROUND(I15*(1+J15/30),1))) | L15: =IF(K15="","",IF(K15>=PRs!C5,"PR!",""))
A16: Day 2 - Light | B16: ='Start Here'!$B$7+37 | C16: Deadlift | D16: 3 | E16: 6 | F16: 75 | G16: =Maxes!E4 | H16: =IF(OR(G16="",F16=""),"",MROUND(G16*F16/100,'Start Here'!$B$6)) | K16: =IF(OR(I16="",J16=""),"",IF(J16=1,I16,ROUND(I16*(1+J16/30),1))) | L16: =IF(K16="","",IF(K16>=PRs!C4,"PR!",""))
A17: Day 2 - Light | B17: ='Start Here'!$B$7+37 | C17: Chin-up | D17: 3 | E17: 6-10 | K17: =IF(OR(I17="",J17=""),"",IF(J17=1,I17,ROUND(I17*(1+J17/30),1))) | L17: =IF(K17="","",IF(K17>=PRs!C53,"PR!","")) | N17: Leave 1-2 reps in the tank; add weight when you hit the top of the range
A18: Day 2 - Light | B18: ='Start Here'!$B$7+37 | C18: Plank | D18: 3 | E18: 30-60s | K18: =IF(OR(I18="",J18=""),"",IF(J18=1,I18,ROUND(I18*(1+J18/30),1))) | L18: =IF(K18="","",IF(K18>=PRs!C56,"PR!","")) | N18: Leave 1-2 reps in the tank; add weight when you hit the top of the range
A19: Day 3 - Variations | B19: ='Start Here'!$B$7+39 | C19: Box Jump | D19: 4 | E19: 3 | H19: =IFERROR(IF(PRs!D69<'Start Here'!$H$15,'Start Here'!$H$15,IF(PRs!D69<'Start Here'!$H$16,'Start Here'!$H$16,IF(PRs!D69<'Start Here'!$H$17,'Start Here'!$H$17,IF(PRs!D69<'Start Here'!$H$18,'Start Here'!$H$18,"Elite!")))),"") | L19: =IF(I19="","",IF(I19>=PRs!D69,"PR!","")) | N19: Explode up, land softly, STEP down. Full reset between reps. Log your box height; check the standards
A20: Day 3 - Variations | B20: ='Start Here'!$B$7+39 | C20: Power Clean | D20: 4 | E20: 3 | F20: 75 | G20: =Maxes!E42 | H20: =IF(OR(G20="",F20=""),"",MROUND(G20*F20/100,'Start Here'!$B$6)) | K20: =IF(OR(I20="",J20=""),"",IF(J20=1,I20,ROUND(I20*(1+J20/30),1))) | L20: =IF(K20="","",IF(K20>=PRs!C42,"PR!",""))
A21: Day 3 - Variations | B21: ='Start Here'!$B$7+39 | C21: Pause Squat | D21: 3 | E21: 6 | F21: 75 | G21: =Maxes!E9 | H21: =IF(OR(G21="",F21=""),"",MROUND(G21*F21/100,'Start Here'!$B$6)) | K21: =IF(OR(I21="",J21=""),"",IF(J21=1,I21,ROUND(I21*(1+J21/30),1))) | L21: =IF(K21="","",IF(K21>=PRs!C9,"PR!",""))
A22: Day 3 - Variations | B22: ='Start Here'!$B$7+39 | C22: 2-Board Press | D22: 3 | E22: 6 | F22: 75 | G22: =Maxes!E16 | H22: =IF(OR(G22="",F22=""),"",MROUND(G22*F22/100,'Start Here'!$B$6)) | K22: =IF(OR(I22="",J22=""),"",IF(J22=1,I22,ROUND(I22*(1+J22/30),1))) | L22: =IF(K22="","",IF(K22>=PRs!C16,"PR!",""))
A23: Day 3 - Variations | B23: ='Start Here'!$B$7+39 | C23: Deficit Deadlift | D23: 3 | E23: 6 | F23: 67.5 | G23: =Maxes!E24 | H23: =IF(OR(G23="",F23=""),"",MROUND(G23*F23/100,'Start Here'!$B$6)) | K23: =IF(OR(I23="",J23=""),"",IF(J23=1,I23,ROUND(I23*(1+J23/30),1))) | L23: =IF(K23="","",IF(K23>=PRs!C24,"PR!",""))
A24: Day 3 - Variations | B24: ='Start Here'!$B$7+39 | C24: Incline Dumbbell Press | D24: 3 | E24: 8-12 | K24: =IF(OR(I24="",J24=""),"",IF(J24=1,I24,ROUND(I24*(1+J24/30),1))) | L24: =IF(K24="","",IF(K24>=PRs!C57,"PR!","")) | N24: Leave 1-2 reps in the tank; add weight when you hit the top of the range
A25: Day 3 - Variations | B25: ='Start Here'!$B$7+39 | C25: Triceps Pushdown | D25: 3 | E25: 10-15 | K25: =IF(OR(I25="",J25=""),"",IF(J25=1,I25,ROUND(I25*(1+J25/30),1))) | L25: =IF(K25="","",IF(K25>=PRs!C59,"PR!","")) | N25: Leave 1-2 reps in the tank; add weight when you hit the top of the range

Sheet Week 07
A1: Week 7 - Cycle 1 - Transmutation
A2: < Week 06 | C2: Start Here | E2: Week 08 >
A3: Bodyweight this week | D3: Weigh in once this week: same morning routine, before eating.
A5: Day | B5: Date | C5: Exercise | D5: Sets | E5: Reps | F5: % TM | G5: Training max | H5: Weight / target | I5: Actual (weight, height or distance) | J5: Actual reps | K5: Est. 1RM | L5: PR | M5: Notes | N5: Guidance
A6: Day 1 - Heavy | B6: ='Start Here'!$B$7+42 | C6: Box Jump | D6: 4 | E6: 3 | H6: =IFERROR(IF(PRs!D69<'Start Here'!$H$15,'Start Here'!$H$15,IF(PRs!D69<'Start Here'!$H$16,'Start Here'!$H$16,IF(PRs!D69<'Start Here'!$H$17,'Start Here'!$H$17,IF(PRs!D69<'Start Here'!$H$18,'Start Here'!$H$18,"Elite!")))),"") | L6: =IF(I6="","",IF(I6>=PRs!D69,"PR!","")) | N6: Explode up, land softly, STEP down. Full reset between reps. Log your box height; check the standards
A7: Day 1 - Heavy | B7: ='Start Here'!$B$7+42 | C7: Snatch | D7: 5 | E7: 2 | F7: 82.5 | G7: =Maxes!E6 | H7: =IF(OR(G7="",F7=""),"",MROUND(G7*F7/100,'Start Here'!$B$6)) | K7: =IF(OR(I7="",J7=""),"",IF(J7=1,I7,ROUND(I7*(1+J7/30),1))) | L7: =IF(K7="","",IF(K7>=PRs!C6,"PR!",""))
A8: Day 1 - Heavy | B8: ='Start Here'!$B$7+42 | C8: Squat | D8: 4 | E8: 4 | F8: 82.5 | G8: =Maxes!E2 | H8: =IF(OR(G8="",F8=""),"",MROUND(G8*F8/100,'Start Here'!$B$6)) | K8: =IF(OR(I8="",J8=""),"",IF(J8=1,I8,ROUND(I8*(1+J8/30),1))) | L8: =IF(K8="","",IF(K8>=PRs!C2,"PR!",""))
A9: Day 1 - Heavy | B9: ='Start Here'!$B$7+42 | C9: Bench Press | D9: 4 | E9: 4 | F9: 82.5 | G9: =Maxes!E3 | H9: =IF(OR(G9="",F9=""),"",MROUND(G9*F9/100,'Start Here'!$B$6)) | K9: =IF(OR(I9="",J9=""),"",IF(J9=1,I9,ROUND(I9*(1+J9/30),1))) | L9: =IF(K9="","",IF(K9>=PRs!C3,"PR!",""))
A10: Day 1 - Heavy | B10: ='Start Here'!$B$7+42 | C10: Barbell Row | D10: 3 | E10: 8-10 | K10: =IF(OR(I10="",J10=""),"",IF(J10=1,I10,ROUND(I10*(1+J10/30),1))) | L10: =IF(K10="","",IF(K10>=PRs!C50,"PR!","")) | N10: Leave 1-2 reps in the tank; add weight when you hit the top of the range
A11: Day 1 - Heavy | B11: ='Start Here'!$B$7+42 | C11: Face Pull | D11: 3 | E11: 12-15 | K11: =IF(OR(I11="",J11=""),"",IF(J11=1,I11,ROUND(I11*(1+J11/30),1))) | L11: =IF(K11="","",IF(K11>=PRs!C51,"PR!","")) | N11: Leave 1-2 reps in the tank; add weight when you hit the top of the range
A12: Day 2 - Light | B12: ='Start Here'!$B$7+44 | C12: Broad Jump | D12: 4 | E12: 3 | L12: =IF(I12="","",IF(I12>=PRs!D70,"PR!","")) | N12: Two-foot jump for distance, stick the landing. Full reset between reps. Log your best distance
A13: Day 2 - Light | B13: ='Start Here'!$B$7+44 | C13: Clean & Jerk | D13: 5 | E13: 2 | F13: 82.5 | G13: =Maxes!E7 | H13: =IF(OR(G13="",F13=""),"",MROUND(G13*F13/100,'Start Here'!$B$6)) | K13: =IF(OR(I13="",J13=""),"",IF(J13=1,I13,ROUND(I13*(1+J13/30),1))) | L13: =IF(K13="","",IF(K13>=PRs!C7,"PR!",""))
A14: Day 2 - Light | B14: ='Start Here'!$B$7+44 | C14: Squat | D14: 3 | E14: 6 | F14: 70 | G14: =Maxes!E2 | H14: =IF(OR(G14="",F14=""),"",MROUND(G14*F14/100,'Start Here'!$B$6)) | K14: =IF(OR(I14="",J14=""),"",IF(J14=1,I14,ROUND(I14*(1+J14/30),1))) | L14: =IF(K14="","",IF(K14>=PRs!C2,"PR!",""))
A15: Day 2 - Light | B15: ='Start Here'!$B$7+44 | C15: Overhead Press | D15: 3 | E15: 6 | F15: 77.5 | G15: =Maxes!E5 | H15: =IF(OR(G15="",F15=""),"",MROUND(G15*F15/100,'Start Here'!$B$6)) | K15: =IF(OR(I15="",J15=""),"",IF(J15=1,I15,ROUND(I15*(1+J15/30),1))) | L15: =IF(K15="","",IF(K15>=PRs!C5,"PR!",""))
A16: Day 2 - Light | B16: ='Start Here'!$B$7+44 | C16: Deadlift | D16: 3 | E16: 6 | F16: 77.5 | G16: =Maxes!E4 | H16: =IF(OR(G16="",F16=""),"",MROUND(G16*F16/100,'Start Here'!$B$6)) | K16: =IF(OR(I16="",J16=""),"",IF(J16=1,I16,ROUND(I16*(1+J16/30),1))) | L16: =IF(K16="","",IF(K16>=PRs!C4,"PR!",""))
A17: Day 2 - Light | B17: ='Start Here'!$B$7+44 | C17: Chin-up | D17: 3 | E17: 6-10 | K17: =IF(OR(I17="",J17=""),"",IF(J17=1,I17,ROUND(I17*(1+J17/30),1))) | L17: =IF(K17="","",IF(K17>=PRs!C53,"PR!","")) | N17: Leave 1-2 reps in the tank; add weight when you hit the top of the range
A18: Day 2 - Light | B18: ='Start Here'!$B$7+44 | C18: Plank | D18: 3 | E18: 30-60s | K18: =IF(OR(I18="",J18=""),"",IF(J18=1,I18,ROUND(I18*(1+J18/30),1))) | L18: =IF(K18="","",IF(K18>=PRs!C56,"PR!","")) | N18: Leave 1-2 reps in the tank; add weight when you hit the top of the range
A19: Day 3 - Variations | B19: ='Start Here'!$B$7+46 | C19: Box Jump | D19: 4 | E19: 3 | H19: =IFERROR(IF(PRs!D69<'Start Here'!$H$15,'Start Here'!$H$15,IF(PRs!D69<'Start Here'!$H$16,'Start Here'!$H$16,IF(PRs!D69<'Start Here'!$H$17,'Start Here'!$H$17,IF(PRs!D69<'Start Here'!$H$18,'Start Here'!$H$18,"Elite!")))),"") | L19: =IF(I19="","",IF(I19>=PRs!D69,"PR!","")) | N19: Explode up, land softly, STEP down. Full reset between reps. Log your box height; check the standards
A20: Day 3 - Variations | B20: ='Start Here'!$B$7+46 | C20: Power Clean | D20: 4 | E20: 3 | F20: 77.5 | G20: =Maxes!E42 | H20: =IF(OR(G20="",F20=""),"",MROUND(G20*F20/100,'Start Here'!$B$6)) | K20: =IF(OR(I20="",J20=""),"",IF(J20=1,I20,ROUND(I20*(1+J20/30),1))) | L20: =IF(K20="","",IF(K20>=PRs!C42,"PR!",""))
A21: Day 3 - Variations | B21: ='Start Here'!$B$7+46 | C21: Pause Squat | D21: 3 | E21: 6 | F21: 77.5 | G21: =Maxes!E9 | H21: =IF(OR(G21="",F21=""),"",MROUND(G21*F21/100,'Start Here'!$B$6)) | K21: =IF(OR(I21="",J21=""),"",IF(J21=1,I21,ROUND(I21*(1+J21/30),1))) | L21: =IF(K21="","",IF(K21>=PRs!C9,"PR!",""))
A22: Day 3 - Variations | B22: ='Start Here'!$B$7+46 | C22: 2-Board Press | D22: 3 | E22: 6 | F22: 77.5 | G22: =Maxes!E16 | H22: =IF(OR(G22="",F22=""),"",MROUND(G22*F22/100,'Start Here'!$B$6)) | K22: =IF(OR(I22="",J22=""),"",IF(J22=1,I22,ROUND(I22*(1+J22/30),1))) | L22: =IF(K22="","",IF(K22>=PRs!C16,"PR!",""))
A23: Day 3 - Variations | B23: ='Start Here'!$B$7+46 | C23: Deficit Deadlift | D23: 3 | E23: 6 | F23: 70 | G23: =Maxes!E24 | H23: =IF(OR(G23="",F23=""),"",MROUND(G23*F23/100,'Start Here'!$B$6)) | K23: =IF(OR(I23="",J23=""),"",IF(J23=1,I23,ROUND(I23*(1+J23/30),1))) | L23: =IF(K23="","",IF(K23>=PRs!C24,"PR!",""))
A24: Day 3 - Variations | B24: ='Start Here'!$B$7+46 | C24: Incline Dumbbell Press | D24: 3 | E24: 8-12 | K24: =IF(OR(I24="",J24=""),"",IF(J24=1,I24,ROUND(I24*(1+J24/30),1))) | L24: =IF(K24="","",IF(K24>=PRs!C57,"PR!","")) | N24: Leave 1-2 reps in the tank; add weight when you hit the top of the range
A25: Day 3 - Variations | B25: ='Start Here'!$B$7+46 | C25: Triceps Pushdown | D25: 3 | E25: 10-15 | K25: =IF(OR(I25="",J25=""),"",IF(J25=1,I25,ROUND(I25*(1+J25/30),1))) | L25: =IF(K25="","",IF(K25>=PRs!C59,"PR!","")) | N25: Leave 1-2 reps in the tank; add weight when you hit the top of the range

Sheet Week 08
A1: Week 8 - Cycle 1 - Deload
A2: < Week 07 | C2: Start Here | E2: Week 09 >
A3: Bodyweight this week | D3: Weigh in once this week: same morning routine, before eating.
A5: Day | B5: Date | C5: Exercise | D5: Sets | E5: Reps | F5: % TM | G5: Training max | H5: Weight / target | I5: Actual (weight, height or distance) | J5: Actual reps | K5: Est. 1RM | L5: PR | M5: Notes | N5: Guidance
A6: Day 1 - Heavy | B6: ='Start Here'!$B$7+49 | C6: Box Jump | D6: 2 | E6: 3 | H6: =IFERROR(IF(PRs!D69<'Start Here'!$H$15,'Start Here'!$H$15,IF(PRs!D69<'Start Here'!$H$16,'Start Here'!$H$16,IF(PRs!D69<'Start Here'!$H$17,'Start Here'!$H$17,IF(PRs!D69<'Start Here'!$H$18,'Start Here'!$H$18,"Elite!")))),"") | L6: =IF(I6="","",IF(I6>=PRs!D69,"PR!","")) | N6: Explode up, land softly, STEP down. Full reset between reps. Log your box height; check the standards
A7: Day 1 - Heavy | B7: ='Start Here'!$B$7+49 | C7: Snatch | D7: 2 | E7: 2 | F7: 65 | G7: =Maxes!E6 | H7: =IF(OR(G7="",F7=""),"",MROUND(G7*F7/100,'Start Here'!$B$6)) | K7: =IF(OR(I7="",J7=""),"",IF(J7=1,I7,ROUND(I7*(1+J7/30),1))) | L7: =IF(K7="","",IF(K7>=PRs!C6,"PR!","")) | N7: Easy week - move fast, recover
A8: Day 1 - Heavy | B8: ='Start Here'!$B$7+49 | C8: Squat | D8: 2 | E8: 5 | F8: 65 | G8: =Maxes!E2 | H8: =IF(OR(G8="",F8=""),"",MROUND(G8*F8/100,'Start Here'!$B$6)) | K8: =IF(OR(I8="",J8=""),"",IF(J8=1,I8,ROUND(I8*(1+J8/30),1))) | L8: =IF(K8="","",IF(K8>=PRs!C2,"PR!","")) | N8: Easy week - move fast, recover
